<?xml version="1.0" encoding="utf-8"?>
<!--
  ============================================================================
  jqr 双机械臂人形上半身机器人 URDF 描述
  ============================================================================
  原始模型：SolidWorks 装配体 jqr.SLDASM，通过 SW2URDF Exporter v1.6.0 导出
  ROS2 适配：手动迁移，修正关节限位、添加运动链注释

  运动链结构：
    base_link (大腿/固定基座)
      └── joint_1 [Z旋转, 腰部] ──▶ link_1 (上躯干)
           ├── joint_l_2 [X] ──▶ Link_l_2 (左肩1)
           │    └── joint_l_3 [Y] ──▶ Link_l_3 (左肩2)
           │         └── joint_l_4 [Z] ──▶ Link_l_4 (左肩3)
           │              └── joint_l_5 [X] ──▶ Link_l_5 (左肘1)
           │                   └── joint_l_6 [Z] ──▶ Link_l_6 (左腕1)
           │                        └── joint_l_7 [X] ──▶ Link_l_7 (左手末端)
           └── joint_r_2 [X] ──▶ Link_r_2 (右肩1)
                └── joint_r_3 [Y] ──▶ Link_r_3 (右肩2)
                     └── joint_r_4 [Z] ──▶ Link_r_4 (右肩3)
                          └── joint_r_5 [X] ──▶ Link_r_5 (右肘1)
                               └── joint_r_6 [Z] ──▶ Link_r_6 (右腕1)
                                    └── joint_r_7 [X] ──▶ Link_r_7 (右手末端)

  关节限位：全部 ±π rad (±180°)，力矩 100 N·m，速度 1.0 rad/s

  适用任务：交通指挥手势（停止/直行/左转/右转/减速/靠边停车/变道/待转）

  原 SW 组件对应：
    leg^jqr-1     → base_link  (大腿)
    qugan^jqr-1   → link_1     (躯干)
    l_jian_*      → 左肩关节
    l_zhou_*      → 左肘关节
    zuoshou-1     → 左手
    r_jian_*      → 右肩关节
    r_zhou_*      → 右肘关节
    youshou-1     → 右手
  ============================================================================
-->
<robot
  name="jqr">
  <!-- ============================================================ -->
  <!-- base_link: 大腿 / 固定基座 (对应 SW 组件: leg^jqr-1)          -->
  <!-- 质量: 25.73 kg                                                -->
  <!-- ============================================================ -->
  <link
    name="base_link">
    <inertial>
      <origin
        xyz="-7.28257887112893E-06 0.00313712189482795 -0.510442515287971"
        rpy="0 0 0" />
      <mass
        value="25.7309030479168" />
      <inertia
        ixx="0.131564424573315"
        ixy="9.22312184388478E-06"
        ixz="-1.92259655939609E-07"
        iyy="0.12863710328844"
        iyz="0.000576826622898757"
        izz="0.0431477760395514" />
    </inertial>
    <visual>
      <origin
        xyz="0 0 0"
        rpy="0 0 0" />
      <geometry>
        <mesh
          filename="package://jqr_description/meshes/base_link.STL" />
      </geometry>
      <material
        name="">
        <color
          rgba="0.752941176470588 0.752941176470588 0.752941176470588 1" />
      </material>
    </visual>
    <collision>
      <origin
        xyz="0 0 0"
        rpy="0 0 0" />
      <geometry>
        <mesh
          filename="package://jqr_description/meshes/base_link.STL" />
      </geometry>
    </collision>
  </link>

  <!-- ============================================================ -->
  <!-- link_1: 上躯干 (对应 SW 组件: qugan^jqr-1)                    -->
  <!-- 质量: 18.06 kg                                                -->
  <!-- ============================================================ -->
  <link
    name="link_1">
    <inertial>
      <origin
        xyz="-3.66716048354199E-07 0.01733512366571 0.204933038476789"
        rpy="0 0 0" />
      <mass
        value="18.0550443856409" />
      <inertia
        ixx="0.0703445252773168"
        ixy="5.67686395963026E-07"
        ixz="-1.04936822351132E-06"
        iyy="0.126050912527544"
        iyz="4.33234114295336E-05"
        izz="0.101749713011065" />
    </inertial>
    <visual>
      <origin
        xyz="0 0 0"
        rpy="0 0 0" />
      <geometry>
        <mesh
          filename="package://jqr_description/meshes/link_1.STL" />
      </geometry>
      <material
        name="">
        <color
          rgba="0.752941176470588 0.752941176470588 0.752941176470588 1" />
      </material>
    </visual>
    <collision>
      <origin
        xyz="0 0 0"
        rpy="0 0 0" />
      <geometry>
        <mesh
          filename="package://jqr_description/meshes/link_1.STL" />
      </geometry>
    </collision>
  </link>

  <!-- joint_1: 腰部旋转关节 (大腿 → 上躯干，绕 Z 轴) -->
  <joint
    name="joint_1"
    type="revolute">
    <origin
      xyz="0 0 0"
      rpy="0 0 0" />
    <parent
      link="base_link" />
    <child
      link="link_1" />
    <axis
      xyz="0 0 -1" />
    <limit
      lower="-3.14159"
      upper="3.14159"
      effort="100"
      velocity="1.0" />
  </joint>

  <!-- ============================================================ -->
  <!-- 左臂 Link_l_2: 左肩1 (对应 SW 组件: l_jian_1^jqr-1)         -->
  <!-- ============================================================ -->
  <link
    name="Link_l_2">
    <inertial>
      <origin
        xyz="0.0192116330700638 0.00210607415629638 1.72593120864595E-07"
        rpy="0 0 0" />
      <mass
        value="0.326987226634881" />
      <inertia
        ixx="0.000337004873840184"
        ixy="-2.5379498108827E-05"
        ixz="-7.47610000146244E-08"
        iyy="0.000304711615462641"
        iyz="1.92480172582897E-09"
        izz="0.000391511792737935" />
    </inertial>
    <visual>
      <origin
        xyz="0 0 0"
        rpy="0 0 0" />
      <geometry>
        <mesh
          filename="package://jqr_description/meshes/Link_l_2.STL" />
      </geometry>
      <material
        name="">
        <color
          rgba="0.752941176470588 0.752941176470588 0.752941176470588 1" />
      </material>
    </visual>
    <collision>
      <origin
        xyz="0 0 0"
        rpy="0 0 0" />
      <geometry>
        <mesh
          filename="package://jqr_description/meshes/Link_l_2.STL" />
      </geometry>
    </collision>
  </link>

  <!-- joint_l_2: 左肩滚动 (上躯干 → 左肩1，绕 X 轴) -->
  <joint
    name="joint_l_2"
    type="revolute">
    <origin
      xyz="0.18 0 0.2957"
      rpy="0 0 0" />
    <parent
      link="link_1" />
    <child
      link="Link_l_2" />
    <axis
      xyz="-1 0 0" />
    <limit
      lower="-3.14159"
      upper="3.14159"
      effort="100"
      velocity="1.0" />
  </joint>

  <!-- Link_l_3: 左肩2 (对应 SW 组件: l_jian_2^jqr-1) -->
  <link
    name="Link_l_3">
    <inertial>
      <origin
        xyz="5.79342129825022E-13 0.0188909489631652 -0.0114828840417226"
        rpy="0 0 0" />
      <mass
        value="0.298520124158937" />
      <inertia
        ixx="0.000193885158977959"
        ixy="-1.99513392221959E-15"
        ixz="1.16639876114517E-15"
        iyy="0.000128830758080107"
        iyz="3.80320921264696E-05"
        izz="0.000162377820693639" />
    </inertial>
    <visual>
      <origin
        xyz="0 0 0"
        rpy="0 0 0" />
      <geometry>
        <mesh
          filename="package://jqr_description/meshes/Link_l_3.STL" />
      </geometry>
      <material
        name="">
        <color
          rgba="0.752941176470588 0.752941176470588 0.752941176470588 1" />
      </material>
    </visual>
    <collision>
      <origin
        xyz="0 0 0"
        rpy="0 0 0" />
      <geometry>
        <mesh
          filename="package://jqr_description/meshes/Link_l_3.STL" />
      </geometry>
    </collision>
  </link>

  <!-- joint_l_3: 左肩俯仰 (左肩1 → 左肩2，绕 Y 轴) -->
  <joint
    name="joint_l_3"
    type="revolute">
    <origin
      xyz="0.053909 -0.028 0"
      rpy="0 0 0" />
    <parent
      link="Link_l_2" />
    <child
      link="Link_l_3" />
    <axis
      xyz="0 1 0" />
    <limit
      lower="-3.14159"
      upper="3.14159"
      effort="100"
      velocity="1.0" />
  </joint>

  <!-- Link_l_4: 左肩3 (对应 SW 组件: l_jian_3^jqr-1) -->
  <link
    name="Link_l_4">
    <inertial>
      <origin
        xyz="-0.00346032389871015 1.65136695429169E-08 -0.108516866875203"
        rpy="0 0 0" />
      <mass
        value="0.671082140232489" />
      <inertia
        ixx="0.00084543734485534"
        ixy="3.13098312956249E-10"
        ixz="-1.49774637729417E-05"
        iyy="0.000856715139405768"
        iyz="1.29726209040003E-10"
        izz="0.000474774451848715" />
    </inertial>
    <visual>
      <origin
        xyz="0 0 0"
        rpy="0 0 0" />
      <geometry>
        <mesh
          filename="package://jqr_description/meshes/Link_l_4.STL" />
      </geometry>
      <material
        name="">
        <color
          rgba="0.752941176470588 0.752941176470588 0.752941176470588 1" />
      </material>
    </visual>
    <collision>
      <origin
        xyz="0 0 0"
        rpy="0 0 0" />
      <geometry>
        <mesh
          filename="package://jqr_description/meshes/Link_l_4.STL" />
      </geometry>
    </collision>
  </link>

  <!-- joint_l_4: 左肩偏航 (左肩2 → 左肩3，绕 Z 轴) -->
  <joint
    name="joint_l_4"
    type="revolute">
    <origin
      xyz="0 0.0285 -0.038"
      rpy="0 0 0" />
    <parent
      link="Link_l_3" />
    <child
      link="Link_l_4" />
    <axis
      xyz="0 0 -1" />
    <limit
      lower="-3.14159"
      upper="3.14159"
      effort="100"
      velocity="1.0" />
  </joint>

  <!-- Link_l_5: 左肘1 (对应 SW 组件: l_zhou_1^jqr-2) -->
  <link
    name="Link_l_5">
    <inertial>
      <origin
        xyz="0.0298252395509881 2.69584074619189E-07 -0.0111377145766401"
        rpy="0 0 0" />
      <mass
        value="0.326042834726433" />
      <inertia
        ixx="0.000196478803920671"
        ixy="3.15590879514583E-09"
        ixz="-1.5664356935537E-05"
        iyy="0.000291950260895777"
        iyz="-9.50914655149448E-08"
        izz="0.00022447445297539" />
    </inertial>
    <visual>
      <origin
        xyz="0 0 0"
        rpy="0 0 0" />
      <geometry>
        <mesh
          filename="package://jqr_description/meshes/Link_l_5.STL" />
      </geometry>
      <material
        name="">
        <color
          rgba="0.752941176470588 0.752941176470588 0.752941176470588 1" />
      </material>
    </visual>
    <collision>
      <origin
        xyz="0 0 0"
        rpy="0 0 0" />
      <geometry>
        <mesh
          filename="package://jqr_description/meshes/Link_l_5.STL" />
      </geometry>
    </collision>
  </link>

  <!-- joint_l_5: 左肘滚动 (左肩3 → 左肘1，绕 X 轴) -->
  <joint
    name="joint_l_5"
    type="revolute">
    <origin
      xyz="-0.026 0 -0.217"
      rpy="0 0 0" />
    <parent
      link="Link_l_4" />
    <child
      link="Link_l_5" />
    <axis
      xyz="-1 0 0" />
    <limit
      lower="-3.14159"
      upper="3.14159"
      effort="100"
      velocity="1.0" />
  </joint>

  <!-- Link_l_6: 左腕1 (对应 SW 组件: l_zhou_2^jqr-1) -->
  <link
    name="Link_l_6">
    <inertial>
      <origin
        xyz="1.70324152282131E-08 -2.26173746398217E-09 -0.086106964412177"
        rpy="0 0 0" />
      <mass
        value="0.578023782698956" />
      <inertia
        ixx="0.000800669559113827"
        ixy="-1.53348176821043E-10"
        ixz="1.22640139468745E-10"
        iyy="0.000800670815790048"
        iyz="-1.74146203074858E-11"
        izz="0.000441194903910431" />
    </inertial>
    <visual>
      <origin
        xyz="0 0 0"
        rpy="0 0 0" />
      <geometry>
        <mesh
          filename="package://jqr_description/meshes/Link_l_6.STL" />
      </geometry>
      <material
        name="">
        <color
          rgba="0.752941176470588 0.752941176470588 0.752941176470588 1" />
      </material>
    </visual>
    <collision>
      <origin
        xyz="0 0 0"
        rpy="0 0 0" />
      <geometry>
        <mesh
          filename="package://jqr_description/meshes/Link_l_6.STL" />
      </geometry>
    </collision>
  </link>

  <!-- joint_l_6: 左腕偏航 (左肘1 → 左腕1，绕 Z 轴) -->
  <joint
    name="joint_l_6"
    type="revolute">
    <origin
      xyz="0.028 0 -0.051909"
      rpy="0 0 0" />
    <parent
      link="Link_l_5" />
    <child
      link="Link_l_6" />
    <axis
      xyz="0 0 -1" />
    <limit
      lower="-3.14159"
      upper="3.14159"
      effort="100"
      velocity="1.0" />
  </joint>

  <!-- Link_l_7: 左手末端 (对应 SW 组件: zuoshou-1) -->
  <link
    name="Link_l_7">
    <inertial>
      <origin
        xyz="0.0338197212259842 -0.00038985244370715 -0.0594631753688534"
        rpy="0 0 0" />
      <mass
        value="0.692165788318104" />
      <inertia
        ixx="0.000718868972184597"
        ixy="6.07415436106744E-07"
        ixz="7.05799369015941E-05"
        iyy="0.000980193989059306"
        iyz="-4.30720905831231E-06"
        izz="0.000451178675645269" />
    </inertial>
    <visual>
      <origin
        xyz="0 0 0"
        rpy="0 0 0" />
      <geometry>
        <mesh
          filename="package://jqr_description/meshes/Link_l_7.STL" />
      </geometry>
      <material
        name="">
        <color
          rgba="0.752941176470588 0.752941176470588 0.752941176470588 1" />
      </material>
    </visual>
    <collision>
      <origin
        xyz="0 0 0"
        rpy="0 0 0" />
      <geometry>
        <mesh
          filename="package://jqr_description/meshes/Link_l_7.STL" />
      </geometry>
    </collision>
  </link>

  <!-- joint_l_7: 左手滚动 (左腕1 → 左手，绕 X 轴) -->
  <joint
    name="joint_l_7"
    type="revolute">
    <origin
      xyz="-0.031909 0 -0.2123"
      rpy="0 0 0" />
    <parent
      link="Link_l_6" />
    <child
      link="Link_l_7" />
    <axis
      xyz="-1 0 0" />
    <limit
      lower="-3.14159"
      upper="3.14159"
      effort="100"
      velocity="1.0" />
  </joint>

  <!-- ============================================================ -->
  <!-- 右臂 (对称于左臂)                                             -->
  <!-- ============================================================ -->

  <!-- Link_r_2: 右肩1 (对应 SW 组件: r_jian_1^jqr-1) -->
  <link
    name="Link_r_2">
    <inertial>
      <origin
        xyz="-0.0192116330699349 0.00210607415747477 -1.7259312089235E-07"
        rpy="0 0 0" />
      <mass
        value="0.326987226634883" />
      <inertia
        ixx="0.000337004873843299"
        ixy="2.53794981068483E-05"
        ixz="-7.47610000147311E-08"
        iyy="0.00030471161545953"
        iyz="-1.92480172115904E-09"
        izz="0.000391511792737939" />
    </inertial>
    <visual>
      <origin
        xyz="0 0 0"
        rpy="0 0 0" />
      <geometry>
        <mesh
          filename="package://jqr_description/meshes/Link_r_2.STL" />
      </geometry>
      <material
        name="">
        <color
          rgba="0.752941176470588 0.752941176470588 0.752941176470588 1" />
      </material>
    </visual>
    <collision>
      <origin
        xyz="0 0 0"
        rpy="0 0 0" />
      <geometry>
        <mesh
          filename="package://jqr_description/meshes/Link_r_2.STL" />
      </geometry>
    </collision>
  </link>

  <!-- joint_r_2: 右肩滚动 (上躯干 → 右肩1，绕 X 轴) -->
  <joint
    name="joint_r_2"
    type="revolute">
    <origin
      xyz="-0.18 0 0.2957"
      rpy="0 0 0" />
    <parent
      link="link_1" />
    <child
      link="Link_r_2" />
    <axis
      xyz="-1 0 0" />
    <limit
      lower="-3.14159"
      upper="3.14159"
      effort="100"
      velocity="1.0" />
  </joint>

  <!-- Link_r_3: 右肩2 (对应 SW 组件: r_jian_2^jqr-1) -->
  <link
    name="Link_r_3">
    <inertial>
      <origin
        xyz="5.79369885400638E-13 0.0188909489631648 -0.0114828840417226"
        rpy="0 0 0" />
      <mass
        value="0.298520124158937" />
      <inertia
        ixx="0.000193885158977959"
        ixy="-1.99514681727917E-15"
        ixz="1.16642669819463E-15"
        iyy="0.000128830758080107"
        iyz="3.80320921264696E-05"
        izz="0.000162377820693639" />
    </inertial>
    <visual>
      <origin
        xyz="0 0 0"
        rpy="0 0 0" />
      <geometry>
        <mesh
          filename="package://jqr_description/meshes/Link_r_3.STL" />
      </geometry>
      <material
        name="">
        <color
          rgba="0.752941176470588 0.752941176470588 0.752941176470588 1" />
      </material>
    </visual>
    <collision>
      <origin
        xyz="0 0 0"
        rpy="0 0 0" />
      <geometry>
        <mesh
          filename="package://jqr_description/meshes/Link_r_3.STL" />
      </geometry>
    </collision>
  </link>

  <!-- joint_r_3: 右肩俯仰 (右肩1 → 右肩2，绕 Y 轴) -->
  <joint
    name="joint_r_3"
    type="revolute">
    <origin
      xyz="-0.053909 -0.028 0"
      rpy="0 0 0" />
    <parent
      link="Link_r_2" />
    <child
      link="Link_r_3" />
    <axis
      xyz="0 1 0" />
    <limit
      lower="-3.14159"
      upper="3.14159"
      effort="100"
      velocity="1.0" />
  </joint>

  <!-- Link_r_4: 右肩3 (对应 SW 组件: r_jian_3^jqr-1) -->
  <link
    name="Link_r_4">
    <inertial>
      <origin
        xyz="0.00346031416444098 1.3527819975323E-08 -0.100516866875203"
        rpy="0 0 0" />
      <mass
        value="0.671082140232494" />
      <inertia
        ixx="0.000845436699954325"
        ixy="6.39308700574732E-10"
        ixz="1.49773890905778E-05"
        iyy="0.000856715784306792"
        iyz="1.06819155489816E-10"
        izz="0.000474774451848718" />
    </inertial>
    <visual>
      <origin
        xyz="0 0 0"
        rpy="0 0 0" />
      <geometry>
        <mesh
          filename="package://jqr_description/meshes/Link_r_4.STL" />
      </geometry>
      <material
        name="">
        <color
          rgba="0.752941176470588 0.752941176470588 0.752941176470588 1" />
      </material>
    </visual>
    <collision>
      <origin
        xyz="0 0 0"
        rpy="0 0 0" />
      <geometry>
        <mesh
          filename="package://jqr_description/meshes/Link_r_4.STL" />
      </geometry>
    </collision>
  </link>

  <!-- joint_r_4: 右肩偏航 (右肩2 → 右肩3，绕 Z 轴) -->
  <joint
    name="joint_r_4"
    type="revolute">
    <origin
      xyz="0 0.0285 -0.046"
      rpy="0 0 0" />
    <parent
      link="Link_r_3" />
    <child
      link="Link_r_4" />
    <axis
      xyz="0 0 -1" />
    <limit
      lower="-3.14159"
      upper="3.14159"
      effort="100"
      velocity="1.0" />
  </joint>

  <!-- Link_r_5: 右肘1 (对应 SW 组件: r_zhou_1^jqr-1) -->
  <link
    name="Link_r_5">
    <inertial>
      <origin
        xyz="-0.0298252395509881 -2.69584075063278E-07 -0.0111377145766401"
        rpy="0 0 0" />
      <mass
        value="0.326042834726433" />
      <inertia
        ixx="0.000196478803920672"
        ixy="3.15590879529204E-09"
        ixz="1.56643569355369E-05"
        iyy="0.000291950260895778"
        iyz="9.50914655145928E-08"
        izz="0.00022447445297539" />
    </inertial>
    <visual>
      <origin
        xyz="0 0 0"
        rpy="0 0 0" />
      <geometry>
        <mesh
          filename="package://jqr_description/meshes/Link_r_5.STL" />
      </geometry>
      <material
        name="">
        <color
          rgba="0.752941176470588 0.752941176470588 0.752941176470588 1" />
      </material>
    </visual>
    <collision>
      <origin
        xyz="0 0 0"
        rpy="0 0 0" />
      <geometry>
        <mesh
          filename="package://jqr_description/meshes/Link_r_5.STL" />
      </geometry>
    </collision>
  </link>

  <!-- joint_r_5: 右肘滚动 (右肩3 → 右肘1，绕 X 轴) -->
  <joint
    name="joint_r_5"
    type="revolute">
    <origin
      xyz="0.026 0 -0.209"
      rpy="0 0 0" />
    <parent
      link="Link_r_4" />
    <child
      link="Link_r_5" />
    <axis
      xyz="-1 0 0" />
    <limit
      lower="-3.14159"
      upper="3.14159"
      effort="100"
      velocity="1.0" />
  </joint>

  <!-- Link_r_6: 右腕1 (对应 SW 组件: r_zhou_2^jqr-1) -->
  <link
    name="Link_r_6">
    <inertial>
      <origin
        xyz="-0.00346033855104882 -4.15228185168814E-09 -0.100516866875208"
        rpy="0 0 0" />
      <mass
        value="0.671082140232455" />
      <inertia
        ixx="0.000845436494795859"
        ixy="-5.87544273379016E-10"
        ixz="-1.49775842588617E-05"
        iyy="0.000856715989464899"
        iyz="-3.56674661630948E-11"
        izz="0.000474774451848694" />
    </inertial>
    <visual>
      <origin
        xyz="0 0 0"
        rpy="0 0 0" />
      <geometry>
        <mesh
          filename="package://jqr_description/meshes/Link_r_6.STL" />
      </geometry>
      <material
        name="">
        <color
          rgba="0.752941176470588 0.752941176470588 0.752941176470588 1" />
      </material>
    </visual>
    <collision>
      <origin
        xyz="0 0 0"
        rpy="0 0 0" />
      <geometry>
        <mesh
          filename="package://jqr_description/meshes/Link_r_6.STL" />
      </geometry>
    </collision>
  </link>

  <!-- joint_r_6: 右腕偏航 (右肘1 → 右腕1，绕 Z 轴) -->
  <joint
    name="joint_r_6"
    type="revolute">
    <origin
      xyz="-0.028 0 -0.051909"
      rpy="0 0 0" />
    <parent
      link="Link_r_5" />
    <child
      link="Link_r_6" />
    <axis
      xyz="0 0 -1" />
    <limit
      lower="-3.14159"
      upper="3.14159"
      effort="100"
      velocity="1.0" />
  </joint>

  <!-- Link_r_7: 右手末端 (对应 SW 组件: youshou-1) -->
  <link
    name="Link_r_7">
    <inertial>
      <origin
        xyz="0.0340045478253294 -0.000425257715062743 -0.0755426177857008"
        rpy="0 0 0" />
      <mass
        value="0.599500129866304" />
      <inertia
        ixx="0.000674103605294355"
        ixy="-6.01103608688652E-07"
        ixz="-0.000116886113480585"
        iyy="0.00092416178179264"
        iyz="-4.30629254755026E-06"
        izz="0.000417613226815065" />
    </inertial>
    <visual>
      <origin
        xyz="0 0 0"
        rpy="0 0 0" />
      <geometry>
        <mesh
          filename="package://jqr_description/meshes/Link_r_7.STL" />
      </geometry>
      <material
        name="">
        <color
          rgba="0.752941176470588 0.752941176470588 0.752941176470588 1" />
      </material>
    </visual>
    <collision>
      <origin
        xyz="0 0 0"
        rpy="0 0 0" />
      <geometry>
        <mesh
          filename="package://jqr_description/meshes/Link_r_7.STL" />
      </geometry>
    </collision>
  </link>

  <!-- joint_r_7: 右手滚动 (右腕1 → 右手，绕 X 轴) -->
  <joint
    name="joint_r_7"
    type="revolute">
    <origin
      xyz="-0.03225 0 -0.209"
      rpy="0 0 0" />
    <parent
      link="Link_r_6" />
    <child
      link="Link_r_7" />
    <axis
      xyz="-1 0 0" />
    <limit
      lower="-3.14159"
      upper="3.14159"
      effort="100"
      velocity="1.0" />
  </joint>

  <!-- ============================================================ -->
  <!-- ros2_control 硬件接口 (Ignition Gazebo)                       -->
  <!-- ============================================================ -->
  <ros2_control name="IgnitionSystem" type="system">
    <hardware>
      <plugin>ign_ros2_control/IgnitionSystem</plugin>
    </hardware>
    <joint name="joint_1">
      <command_interface name="position"/>
      <state_interface name="position"/>
      <state_interface name="velocity"/>
    </joint>
    <joint name="joint_l_2">
      <command_interface name="position"/>
      <state_interface name="position"/>
      <state_interface name="velocity"/>
    </joint>
    <joint name="joint_l_3">
      <command_interface name="position"/>
      <state_interface name="position"/>
      <state_interface name="velocity"/>
    </joint>
    <joint name="joint_l_4">
      <command_interface name="position"/>
      <state_interface name="position"/>
      <state_interface name="velocity"/>
    </joint>
    <joint name="joint_l_5">
      <command_interface name="position"/>
      <state_interface name="position"/>
      <state_interface name="velocity"/>
    </joint>
    <joint name="joint_l_6">
      <command_interface name="position"/>
      <state_interface name="position"/>
      <state_interface name="velocity"/>
    </joint>
    <joint name="joint_l_7">
      <command_interface name="position"/>
      <state_interface name="position"/>
      <state_interface name="velocity"/>
    </joint>
    <joint name="joint_r_2">
      <command_interface name="position"/>
      <state_interface name="position"/>
      <state_interface name="velocity"/>
    </joint>
    <joint name="joint_r_3">
      <command_interface name="position"/>
      <state_interface name="position"/>
      <state_interface name="velocity"/>
    </joint>
    <joint name="joint_r_4">
      <command_interface name="position"/>
      <state_interface name="position"/>
      <state_interface name="velocity"/>
    </joint>
    <joint name="joint_r_5">
      <command_interface name="position"/>
      <state_interface name="position"/>
      <state_interface name="velocity"/>
    </joint>
    <joint name="joint_r_6">
      <command_interface name="position"/>
      <state_interface name="position"/>
      <state_interface name="velocity"/>
    </joint>
    <joint name="joint_r_7">
      <command_interface name="position"/>
      <state_interface name="position"/>
      <state_interface name="velocity"/>
    </joint>
  </ros2_control>

  <!-- ============================================================ -->
  <!-- Ignition Gazebo 仿真插件                                     -->
  <!-- ============================================================ -->
  <gazebo>
    <plugin filename="libign_ros2_control-system.so"
            name="ign_ros2_control::IgnitionROS2ControlPlugin">
      <ros>
        <namespace>/</namespace>
      </ros>
    </plugin>
  </gazebo>

</robot>
